[2022-08-09 19:36:38,974] {taskinstance.py:1179} INFO - Dependencies all met for <TaskInstance: twitter_dag.grab_tweets scheduled__2022-08-07T00:00:00+00:00 [queued]>
[2022-08-09 19:36:38,996] {taskinstance.py:1179} INFO - Dependencies all met for <TaskInstance: twitter_dag.grab_tweets scheduled__2022-08-07T00:00:00+00:00 [queued]>
[2022-08-09 19:36:38,998] {taskinstance.py:1376} INFO - 
--------------------------------------------------------------------------------
[2022-08-09 19:36:39,007] {taskinstance.py:1377} INFO - Starting attempt 2 of 2
[2022-08-09 19:36:39,008] {taskinstance.py:1378} INFO - 
--------------------------------------------------------------------------------
[2022-08-09 19:36:39,023] {taskinstance.py:1397} INFO - Executing <Task(BashOperator): grab_tweets> on 2022-08-07 00:00:00+00:00
[2022-08-09 19:36:39,035] {standard_task_runner.py:52} INFO - Started process 232 to run task
[2022-08-09 19:36:39,038] {standard_task_runner.py:79} INFO - Running: ['***', 'tasks', 'run', 'twitter_dag', 'grab_tweets', 'scheduled__2022-08-07T00:00:00+00:00', '--job-id', '18', '--raw', '--subdir', 'DAGS_FOLDER/twitter_***.py', '--cfg-path', '/tmp/tmpsnxdkwxc', '--error-file', '/tmp/tmpp_19gfco']
[2022-08-09 19:36:39,043] {standard_task_runner.py:80} INFO - Job 18: Subtask grab_tweets
[2022-08-09 19:36:39,112] {task_command.py:371} INFO - Running <TaskInstance: twitter_dag.grab_tweets scheduled__2022-08-07T00:00:00+00:00 [running]> on host 9389ea9491e2
[2022-08-09 19:36:39,199] {taskinstance.py:1591} INFO - Exporting the following env vars:
AIRFLOW_CTX_DAG_EMAIL=ycattaneo33@gmail.com
AIRFLOW_CTX_DAG_OWNER=***
AIRFLOW_CTX_DAG_ID=twitter_dag
AIRFLOW_CTX_TASK_ID=grab_tweets
AIRFLOW_CTX_EXECUTION_DATE=2022-08-07T00:00:00+00:00
AIRFLOW_CTX_TRY_NUMBER=2
AIRFLOW_CTX_DAG_RUN_ID=scheduled__2022-08-07T00:00:00+00:00
[2022-08-09 19:36:39,203] {subprocess.py:62} INFO - Tmp dir root location: 
 /tmp
[2022-08-09 19:36:39,205] {subprocess.py:74} INFO - Running command: ['bash', '-c', 'python ../grab_tweets.py']
[2022-08-09 19:36:39,220] {subprocess.py:85} INFO - Output:
[2022-08-09 19:36:39,316] {subprocess.py:92} INFO - python: can't open file '../grab_tweets.py': [Errno 2] No such file or directory
[2022-08-09 19:36:39,322] {subprocess.py:96} INFO - Command exited with return code 2
[2022-08-09 19:36:39,336] {taskinstance.py:1909} ERROR - Task failed with exception
Traceback (most recent call last):
  File "/home/airflow/.local/lib/python3.7/site-packages/airflow/operators/bash.py", line 195, in execute
    f'Bash command failed. The command returned a non-zero exit code {result.exit_code}.'
airflow.exceptions.AirflowException: Bash command failed. The command returned a non-zero exit code 2.
[2022-08-09 19:36:39,342] {taskinstance.py:1420} INFO - Marking task as FAILED. dag_id=twitter_dag, task_id=grab_tweets, execution_date=20220807T000000, start_date=20220809T193638, end_date=20220809T193639
[2022-08-09 19:36:39,359] {warnings.py:110} WARNING - /home/***/.local/lib/python3.7/site-packages/***/utils/email.py:119: PendingDeprecationWarning: Fetching SMTP credentials from configuration variables will be deprecated in a future release. Please set credentials using a connection instead.
  send_mime_email(e_from=mail_from, e_to=recipients, mime_msg=msg, conn_id=conn_id, dryrun=dryrun)

[2022-08-09 19:36:39,361] {configuration.py:552} WARNING - section/key [smtp/smtp_user] not found in config
[2022-08-09 19:36:39,362] {email.py:228} INFO - Email alerting: attempt 1
[2022-08-09 19:36:39,374] {configuration.py:552} WARNING - section/key [smtp/smtp_user] not found in config
[2022-08-09 19:36:39,375] {email.py:228} INFO - Email alerting: attempt 1
[2022-08-09 19:36:39,377] {taskinstance.py:1964} ERROR - Failed to send email to: ['ycattaneo33@gmail.com']
Traceback (most recent call last):
  File "/home/airflow/.local/lib/python3.7/site-packages/airflow/models/taskinstance.py", line 1471, in _run_raw_task
    self._execute_task_with_callbacks(context, test_mode)
  File "/home/airflow/.local/lib/python3.7/site-packages/airflow/models/taskinstance.py", line 1618, in _execute_task_with_callbacks
    result = self._execute_task(context, task_orig)
  File "/home/airflow/.local/lib/python3.7/site-packages/airflow/models/taskinstance.py", line 1679, in _execute_task
    result = execute_callable(context=context)
  File "/home/airflow/.local/lib/python3.7/site-packages/airflow/operators/bash.py", line 195, in execute
    f'Bash command failed. The command returned a non-zero exit code {result.exit_code}.'
airflow.exceptions.AirflowException: Bash command failed. The command returned a non-zero exit code 2.

During handling of the above exception, another exception occurred:

Traceback (most recent call last):
  File "/home/airflow/.local/lib/python3.7/site-packages/airflow/models/taskinstance.py", line 2346, in email_alert
    send_email(task.email, subject, html_content)
  File "/home/airflow/.local/lib/python3.7/site-packages/airflow/utils/email.py", line 71, in send_email
    **kwargs,
  File "/home/airflow/.local/lib/python3.7/site-packages/airflow/utils/email.py", line 119, in send_email_smtp
    send_mime_email(e_from=mail_from, e_to=recipients, mime_msg=msg, conn_id=conn_id, dryrun=dryrun)
  File "/home/airflow/.local/lib/python3.7/site-packages/airflow/utils/email.py", line 230, in send_mime_email
    smtp_conn = _get_smtp_connection(smtp_host, smtp_port, smtp_timeout, smtp_ssl)
  File "/home/airflow/.local/lib/python3.7/site-packages/airflow/utils/email.py", line 264, in _get_smtp_connection
    else smtplib.SMTP(host=host, port=port, timeout=timeout)
  File "/usr/local/lib/python3.7/smtplib.py", line 251, in __init__
    (code, msg) = self.connect(host, port)
  File "/usr/local/lib/python3.7/smtplib.py", line 336, in connect
    self.sock = self._get_socket(host, port, self.timeout)
  File "/usr/local/lib/python3.7/smtplib.py", line 307, in _get_socket
    self.source_address)
  File "/usr/local/lib/python3.7/socket.py", line 728, in create_connection
    raise err
  File "/usr/local/lib/python3.7/socket.py", line 716, in create_connection
    sock.connect(sa)
OSError: [Errno 99] Cannot assign requested address

During handling of the above exception, another exception occurred:

Traceback (most recent call last):
  File "/home/airflow/.local/lib/python3.7/site-packages/airflow/models/taskinstance.py", line 1962, in handle_failure
    self.email_alert(error, task)
  File "/home/airflow/.local/lib/python3.7/site-packages/airflow/models/taskinstance.py", line 2348, in email_alert
    send_email(task.email, subject, html_content_err)
  File "/home/airflow/.local/lib/python3.7/site-packages/airflow/utils/email.py", line 71, in send_email
    **kwargs,
  File "/home/airflow/.local/lib/python3.7/site-packages/airflow/utils/email.py", line 119, in send_email_smtp
    send_mime_email(e_from=mail_from, e_to=recipients, mime_msg=msg, conn_id=conn_id, dryrun=dryrun)
  File "/home/airflow/.local/lib/python3.7/site-packages/airflow/utils/email.py", line 230, in send_mime_email
    smtp_conn = _get_smtp_connection(smtp_host, smtp_port, smtp_timeout, smtp_ssl)
  File "/home/airflow/.local/lib/python3.7/site-packages/airflow/utils/email.py", line 264, in _get_smtp_connection
    else smtplib.SMTP(host=host, port=port, timeout=timeout)
  File "/usr/local/lib/python3.7/smtplib.py", line 251, in __init__
    (code, msg) = self.connect(host, port)
  File "/usr/local/lib/python3.7/smtplib.py", line 336, in connect
    self.sock = self._get_socket(host, port, self.timeout)
  File "/usr/local/lib/python3.7/smtplib.py", line 307, in _get_socket
    self.source_address)
  File "/usr/local/lib/python3.7/socket.py", line 728, in create_connection
    raise err
  File "/usr/local/lib/python3.7/socket.py", line 716, in create_connection
    sock.connect(sa)
OSError: [Errno 99] Cannot assign requested address
[2022-08-09 19:36:39,392] {standard_task_runner.py:97} ERROR - Failed to execute job 18 for task grab_tweets (Bash command failed. The command returned a non-zero exit code 2.; 232)
[2022-08-09 19:36:39,419] {local_task_job.py:156} INFO - Task exited with return code 1
[2022-08-09 19:36:39,469] {local_task_job.py:273} INFO - 0 downstream tasks scheduled from follow-on schedule check
